Workbook
Name ____: #REF!
Name __________B1: [0]!__________B1
Name __________bb1: [0]!__________bb1
Name __________cc1: [0]!__________cc1
Name __________dd1: [0]!__________dd1
Name ________B1: [0]!________B1
Name ________bb1: [0]!________bb1
Name ________cc1: [0]!________cc1
Name ________dd1: [0]!________dd1
Name ________rev1: {"'Sheet2'!$A$1:$F$14"}
Name ______rev1: {"'Sheet2'!$A$1:$F$14"}
Name _____B1: [0]!_____B1
Name _____bb1: [0]!_____bb1
Name _____cc1: [0]!_____cc1
Name _____dd1: [0]!_____dd1
Name ____B1: [0]!____B1
Name ____bb1: [0]!____bb1
Name ____cc1: [0]!____cc1
Name ____dd1: [0]!____dd1
Name ___B1: [0]!___B1
Name ___bb1: [0]!___bb1
Name ___cc1: [0]!___cc1
Name ___dd1: [0]!___dd1
Name ___KD2: #REF!
Name ___KD3: #REF!
Name ___KK1: #REF!
Name ___KK2: #REF!
Name ___KK3: #REF!
Name ___rev1: {"'Sheet2'!$A$1:$F$14"}
Name __123Graph_A: #REF!
Name __123Graph_B: #REF!
Name __123Graph_C: #REF!
Name __123Graph_D: #REF!
Name __123Graph_E: #REF!
Name __123Graph_F: #REF!
Name __123Graph_LBL_A: #REF!
Name __123Graph_X: #REF!
Name __B1: [0]!__B1
Name __b2: [0]!__b2
Name __bb1: [0]!__bb1
Name __cc1: [0]!__cc1
Name __CII2: {"offequipsch",#N/A,FALSE,"GTC_Schedule";"onconstsch",#N/A,FALSE,"GTC_Schedule";"techsch",#N/A,FALSE,"GTC_Schedule";"totsch",#N/A,FALSE,"GTC_Schedule"}
Name __dd1: [0]!__dd1
Name __IntlFixup: TRUE
Name __KD2: #REF!
Name __KD3: #REF!
Name __KK1: #REF!
Name __KK2: #REF!
Name __KK3: #REF!
Name __NSO2: {"'Sheet1'!$L$16"}
Name __P3: {#N/A,#N/A,FALSE,"特殊室（ＢＱ表）"}
Name __PK2: {"'장비'!$A$3:$M$12"}
Name __PKG3: {"'장비'!$A$3:$M$12"}
Name __PPP3: {#N/A,#N/A,FALSE,"特殊室（ＢＱ表）"}
Name __PPP33: {#N/A,#N/A,FALSE,"特殊室（ＢＱ表）"}
Name __ppp34: {#N/A,#N/A,FALSE,"特殊室（ＢＱ表）"}
Name __ppp3444: {#N/A,#N/A,FALSE,"特殊室（ＢＱ表）"}
Name __qqq222: {"'장비'!$A$3:$M$12"}
Name __rev1: {"'Sheet2'!$A$1:$F$14"}
Name _01_01_01: #REF!

Sheet hsmt v2
A1: STT | B1: Mã giá | C1: Tên vật tư mới | D1: TSKT mới | E1: Tên ERP | F1: Đvt erp | G1: ĐVT | H1: SL hsmt final | I1: Số lượng hsmt mua sắm trước khi anh Khang cắt, thêm từ gói khác | J1: Đơn giá | K1: Thuế | L1: Thành tiền trước thuế | M1: Thành tiền sau thuế | N1: Tiền thuế | O1: chủng loại | P1: giá trị tương đương | Q1: sản phẩm/tháng | R1: sản phẩm/năm | V1: cocq | W1: Tiến độ | X1: Cơ sở lập dự toán | Y1: HSX/Xuất xứ | Z1: Mã ERP tương tự | AA1: Đơn giá ERP tham khảo | AB1: Thời gian nhập kho | AC1: Sô lượng tồn kho nhà máy | AD1: Số lượng cắt giảm | AE1: KL mua sắm theo QĐ 460 | AF1: Mã VT đang còn tồn kho | AG1: Ghi chú | AH1: Báo giá ASEAN | AJ1: BÁO GIÁ HUY MINH | AL1: BÁO GIÁ HẢI PHÒNG | AN1: Tên Vật tư cũ | AO1: ĐVT cũ | AP1: Khối lượng cũ | AQ1: Mã ERP P.KTAT đề xuất | AR1: Ghi chú final
A2: 1 | B2: TT_S3_DCS_0001+TT_S3_DCS_0013+TT_S3_DCS_0018+TT_S3_DCS_0021+TT_S3_DCS_0030+TT_S3_DCS_0078 | C2: Ổ cứng HDD | D2: Ổ cứng HDD Hãng: WD Ổ cứng HDD 3.5 1TB Loại và tốc độ: SATA 6Gb/s Capacity: 1TB Thông số làm việc : 5V/0.68A; 12V/0.55A | E2: Ổ cứng HDD WD 1TB | F2: Cái | G2: Cái | H2: 9 | I2: 9 | J2: 4533000 | K2: 0.08 | L2: =H2*J2 -> 40797000 | M2: =L2*(1+K2) -> 44060760 | N2: =K2*L2 -> 3263760 | O2: Vật tư/Thiết bị điện | P2: =M2/2 -> 22030380 | Q2: =1.5*(H2*30/365) -> 1.109589 | R2: =1.5*H2 -> 13.5 | S2: 1.11 | T2: =ROUND(R2,2) -> 13.5 | U2: =S2&" sản phẩm/tháng hoặc " &T2& " sản phẩm/năm " -> 1,11 sản phẩm/tháng hoặc 13,5 sản phẩm/năm | V2: CO, CQ | W2: 150 ngày | X2: Đơn giá thấp nhất trong các báo giá | Y2: Western Digital/ Thái Lan | Z2: 3.94.00.032.THA.98.000 | AC2: 0 | AD2: 0 | AE2: 4 | AH2: 4533000 | AI2: Western Digital/ Thái Lan | AJ2: 5340000 | AK2: DELL/ Trung Quốc | AL2: 6300000 | AM2: Asus/ Nhật Bản | AN2: Ổ cứng HDD Hãng : WD Ổ cứng HDD 3.5 1TB Loại và tốc độ: SATA 6Gb/s Capacity: 1TB Thông số làm việc : 5V/0.68A; 12V/0.55A | AO2: Cái | AP2: 4 | AQ2: 3.94.00.032.THA.98.000
A3: 2 | B3: TT_S3_DCS_0002 | C3: Mounting Base: HBS 01 - EPD | D3: Đế Module IO Mác, mã: HBS01-EPD Hãng sản xuất: ABB PR (Product Revision): J hoặc mới hơn | E3: Mounting Base: HBS 01 - EPD | F3: Cái | G3: Cái | H3: 22 | I3: 22 | J3: 25740000 | K3: 0.08 | L3: =H3*J3 -> 566280000 | M3: =L3*(1+K3) -> 611582400 | N3: =K3*L3 -> 45302400 | O3: Vật tư/Thiết bị điện | P3: =M3/2 -> 305791200 | Q3: =1.5*(H3*30/365) -> 2.7123288 | R3: =1.5*H3 -> 33 | S3: =ROUND(Q3,2) -> 2.71 | T3: =ROUND(R3,2) -> 33 | U3: =S3&" sản phẩm/tháng hoặc " &T3& " sản phẩm/năm " -> 2,71 sản phẩm/tháng hoặc 33 sản phẩm/năm | V3: CO, CQ | W3: 150 ngày | X3: Đơn giá thấp nhất trong các báo giá | Y3: ABB/ Pháp | Z3: 3.82.63.102.LTU.00.000 | AA3: 19360000 | AB3: =VLOOKUP(Z3,'[1]Tra giá ERP'!$A$2:$C$25844,3,0) -> Nhập kho vật tư (HĐ:118/2021) theo hóa đơn số 00000001 ngày 05.01.2022 | AC3: 0 | AD3: 0 | AE3: 22 | AH3: 28340000 | AI3: ABB/ Đức | AJ3: 25740000 | AK3: ABB/ Pháp | AL3: 29000000 | AM3: ABB/ Mỹ | AN3: Đế Module IO Mác, mã: HBS01-EPD Hãng sản xuất: ABB | AO3: Cái | AP3: 22 | AQ3: 3.82.63.102.LTU.00.000
A4: 3 | B4: TT_S3_DCS_0003 | C4: Đế gắn module IO SD I/O MOUNTING BASE Model: HBS01-FPH | D4: Đế Module IO Mác, mã: HBS01-FPH Hãng sản xuất: ABB PR (Product Revision): J hoặc mới hơn | E4: Đế gắn module IO SD I/O MOUNTING BASE Model: HBS01-FPH | F4: Cái | G4: Cái | H4: 112 | I4: 112 | J4: 23660000 | K4: 0.08 | L4: =H4*J4 -> 2649920000 | M4: =L4*(1+K4) -> 2861913600 | N4: =K4*L4 -> 211993600 | O4: Vật tư/Thiết bị điện | P4: =M4/2 -> 1430956800 | Q4: =1.5*(H4*30/365) -> 13.808219 | R4: =1.5*H4 -> 168 | S4: =ROUND(Q4,2) -> 13.81 | T4: =ROUND(R4,2) -> 168 | U4: =S4&" sản phẩm/tháng hoặc " &T4& " sản phẩm/năm " -> 13,81 sản phẩm/tháng hoặc 168 sản phẩm/năm | V4: CO, CQ | W4: 150 ngày | X4: Lấy theo đơn giá hợp đồng 40/2025/HĐ-HH ngày 30/5/2025 | Y4: ABB/ Pháp | Z4: 3.94.00.808.MLT.00.000 | AA4: 23660000 | AB4: =VLOOKUP(Z4,'[1]Tra giá ERP'!$A$2:$C$25844,3,0) -> Nhập kho vật tư (HĐ: 40/2025) theo hóa đơn số 00000121 ngày 14.10.2025 | AC4: 0 | AD4: 0 | AE4: 112 | AH4: 29000000 | AI4: ABB/ Đức | AJ4: 25740000 | AK4: ABB/ Pháp | AL4: 30000000 | AM4: ABB/ Mỹ | AN4: Đế Module IO Mác, mã: HBS01-FPH Hãng sản xuất: ABB | AO4: Cái | AP4: 112 | AQ4: 3.94.00.808.MLT.00.000
A5: 4 | B5: TT_S3_DCS_0004 | C5: Mouting base Model: HBS01-FPN | D5: Đế Module IO Mác, mã: HBS01-FPN Hãng sản xuất: ABB PR (Product Revision): J hoặc mới hơn | E5: Mouting base Model: HBS01-FPN | F5: Cái | G5: Cái | H5: 26 | I5: 26 | J5: 23500000 | K5: 0.08 | L5: =H5*J5 -> 611000000 | M5: =L5*(1+K5) -> 659880000 | N5: =K5*L5 -> 48880000 | O5: Vật tư/Thiết bị điện | P5: =M5/2 -> 329940000 | Q5: =1.5*(H5*30/365) -> 3.2054795 | R5: =1.5*H5 -> 39 | S5: =ROUND(Q5,2) -> 3.21 | T5: =ROUND(R5,2) -> 39 | U5: =S5&" sản phẩm/tháng hoặc " &T5& " sản phẩm/năm " -> 3,21 sản phẩm/tháng hoặc 39 sản phẩm/năm | V5: CO, CQ | W5: 150 ngày | X5: Lấy theo đơn giá hợp đồng 25/2025/HĐ-HH ngày 24/4/2025 | Y5: ABB/ Pháp | Z5: 3.94.00.811.IND.00.000 | AA5: 23500000 | AB5: =VLOOKUP(Z5,'[1]Tra giá ERP'!$A$2:$C$25844,3,0) -> Nhập kho vật tư (HĐ: 25/2025) theo hóa đơn số 00000070 ngày 26.05.2025 | AC5: 0 | AD5: 0 | AE5: 26 | AH5: 29500000 | AI5: ABB/ Đức | AJ5: 25740000 | AK5: ABB/ Pháp | AL5: 31500000 | AM5: ABB/ Mỹ | AN5: Đế Module IO Mác, mã: HBS01-FPN Hãng sản xuất: ABB | AO5: Cái | AP5: 26 | AQ5: 3.94.00.811.IND.00.000
A6: 5 | B6: TT_S3_DCS_0005+TT_S3_DCS_0009+TT_S3_DCS_0011+TT_S3_DCS_0014+TT_S3_DCS_0015+TT_S3_DCS_0019+TT_S3_DCS_0022+TT_S3_DCS_0025+TT_S3_DCS_0028+TT_S3_DCS_0031+TT_S3_DCS_0034+TT_S3_DCS_0037+TT_S3_DCS_0040+TT_S3_DCS_0043+TT_S3_DCS_0045+TT_S3_DCS_0047+TT_S3_DCS_0049+TT_S3_DCS_0051+TT_S3_DCS_0053+TT_S3_DCS_0056+TT_S3_DCS_0061+TT_S3_DCS_0065+TT_S3_DCS_0070+TT_S3_DCS_0073 | C6: Túi chống ẩm Silicagel có dây treo 0,5kg/túi | D6: Túi chống ẩm Silicagel có dây treo 0,5kg/túi | E6: Túi chống ẩm Silicagel có dây treo 0,5kg/túi | F6: Túi | G6: Túi | H6: 204 | I6: 204 | J6: 39000 | K6: 0.08 | L6: =H6*J6 -> 7956000 | M6: =L6*(1+K6) -> 8592480 | N6: =K6*L6 -> 636480 | O6: Vật tư/Thiết bị cơ khí | P6: =M6/2 -> 4296240 | Q6: =1.5*(H6*30/365) -> 25.150685 | R6: =1.5*H6 -> 306 | S6: =ROUND(Q6,2) -> 25.15 | T6: =ROUND(R6,2) -> 306 | U6: =S6&" sản phẩm/tháng hoặc " &T6& " sản phẩm/năm " -> 25,15 sản phẩm/tháng hoặc 306 sản phẩm/năm | W6: 150 ngày | X6: Đơn giá thấp nhất trong các báo giá | Y6: Minh Ngọc/ Việt Nam | Z6: 1.81.08.506.VIE.00.000 | AA6: 125000 | AB6: =VLOOKUP(Z6,'[1]Tra giá ERP'!$A$2:$C$25844,3,0) -> Nhập kho vật tư (HĐ:121/2023) theo hóa đơn số 00000216 ngày 13.12.2023 | AC6: 0 | AD6: 0 | AE6: 100 | AH6: 39000 | AI6: SECCO/ Việt Nam | AJ6: 42000 | AK6: Minh Ngọc/ Việt Nam | AL6: 45000 | AM6: Thịnh Phong/ Việt Nam | AN6: Túi chống ẩm Silicagel có dây treo 0,5kg/túi | AO6: Túi | AP6: 100 | AQ6: 1.81.08.506.VIE.00.000
A7: 6 | B7: TT_S3_DCS_0006 | C7: Quạt hút tủ điện SNUON 300x300mm | D7: Quạt hút tủ điện SNUON 300x300mm: Điện áp: 200V – 240V Hãng: SNUON Kích thước: 300x300x38mm Tốc độ: 2800-3250rpm Cánh quạt làm bằng nhựa Plastic cao cấp Khung quạt làm bằng kim loại: Chắc chắn | E7: #N/A | F7: #N/A | G7: Cái | H7: 50 | I7: 50 | J7: 613000 | K7: 0.08 | L7: =H7*J7 -> 30650000 | M7: =L7*(1+K7) -> 33102000 | N7: =K7*L7 -> 2452000 | O7: Vật tư/Thiết bị điện | P7: =M7/2 -> 16551000 | Q7: =1.5*(H7*30/365) -> 6.1643836 | R7: =1.5*H7 -> 75 | S7: =ROUND(Q7,2) -> 6.16 | T7: =ROUND(R7,2) -> 75 | U7: =S7&" sản phẩm/tháng hoặc " &T7& " sản phẩm/năm " -> 6,16 sản phẩm/tháng hoặc 75 sản phẩm/năm | W7: 150 ngày | X7: Đơn giá thấp nhất trong các báo giá | Y7: SNUON/ Thái Lan | Z7: chưa có mã ERP | AB7: =VLOOKUP(Z7,'[1]Tra giá ERP'!$A$2:$C$25844,3,0) -> #N/A | AC7: 0 | AD7: 0 | AE7: 50 | AH7: 613000 | AI7: SNUON/ Thái Lan | AJ7: 823000 | AK7: SNUON/ Trung Quốc | AL7: 914000 | AM7: SNUON/ Trung Quốc | AN7: Quạt hút tủ điện SNUON 300x300mm: Điện áp: 200V – 240V Hãng: SNUON Kích thước: 300x300x38mm Tốc độ: 2800-3250rpm Cánh quạt làm bằng nhựa Plastic cao cấp Khung quạt làm bằng kim loại: Chắc chắn | AO7: Cái | AP7: 50 | AQ7: chưa có mã ERP
A8: 7 | B8: TT_S3_DCS_0055 | C8: Ổ cứng SSD Samsung 870 Evo 1TB | D8: SSD Samsung 870 Evo 1TB Kích thước: 2.5-Inch SATA III MZ-77E1T0BW | E8: Ổ cứng SSD Samsung 870 Evo 1TB | F8: Cái | G8: Cái | H8: 2 | I8: 2 | J8: 7508000 | K8: 0.08 | L8: =H8*J8 -> 15016000 | M8: =L8*(1+K8) -> 16217280 | N8: =K8*L8 -> 1201280 | O8: Vật tư/Thiết bị điện | P8: =M8/2 -> 8108640 | Q8: =1.5*(H8*30/365) -> 0.24657534 | R8: =1.5*H8 -> 3 | S8: =ROUND(Q8,2) -> 0.25 | T8: =ROUND(R8,2) -> 3 | U8: =S8&" sản phẩm/tháng hoặc " &T8& " sản phẩm/năm " -> 0,25 sản phẩm/tháng hoặc 3 sản phẩm/năm | W8: 150 ngày | X8: Đơn giá thấp nhất trong các báo giá | Y8: Samsung/ Hàn Quốc | Z8: 3.94.00.124.CHN.00.000 | AA8: 5500000 | AB8: =VLOOKUP(Z8,'[1]Tra giá ERP'!$A$2:$C$25844,3,0) -> Nhập kho vật tư (HĐ: 34/2025) theo hóa đơn số 00000073 ngày 05.06.2025 | AC8: 0 | AD8: 0 | AE8: 2 | AH8: 8240000 | AI8: Samsung/ Hàn Quốc | AJ8: 7508000 | AK8: Samsung/ Hàn Quốc | AL8: 11000000 | AM8: Samsung/ Hàn Quốc | AN8: SSD Samsung 870 Evo 1TB Kích thước: 2.5-Inch SATA III MZ-77E1T0BW | AO8: Cái | AP8: 2 | AQ8: 3.94.00.124.CHN.00.000
A9: 8 | B9: TT_S3_TM__00356 | C9: Công tắc (Switch) Model: DZ-10GW-1B | D9: Công tắc (Switch) Model: DZ-10GW-1B Điện áp max: 250 VAC/VDC Dòng điện định mức: 10A Số công tắc: DPDT NSX: Omron | E9: #N/A | F9: #N/A | G9: Cái | H9: 13 | I9: 13 | J9: 1150000 | K9: 0.08 | L9: =H9*J9 -> 14950000 | M9: =L9*(1+K9) -> 16146000 | N9: =K9*L9 -> 1196000 | O9: Vật tư/Thiết bị điện | P9: =M9/2 -> 8073000 | Q9: =1.5*(H9*30/365) -> 1.6027397 | R9: =1.5*H9 -> 19.5 | S9: =ROUND(Q9,2) -> 1.6 | T9: =ROUND(R9,2) -> 19.5 | U9: =S9&" sản phẩm/tháng hoặc " &T9& " sản phẩm/năm " -> 1,6 sản phẩm/tháng hoặc 19,5 sản phẩm/năm | W9: 150 ngày | X9: Đơn giá thấp nhất trong các báo giá | Y9: Omron/ Trung Quốc | AA9: #N/A | AB9: =VLOOKUP(Z9,'[1]Tra giá ERP'!$A$2:$C$25844,3,0) -> #N/A | AC9: 0 | AD9: 0 | AE9: 13 | AH9: 2540000 | AI9: Omron/ Nhật Bản | AJ9: 1150000 | AK9: Omron/ Trung Quốc | AL9: 3500000 | AM9: Omron/ Hàn Quốc | AN9: Công tắc (Switch) Model: DZ-10GW-1B; Rated voltage: 10A | AO9: Cái | AP9: 13
A10: 9 | B10: TT_S3_TM__00391 | C10: Vòng đệm tròn cao su/O-ring, KT: ID456.06x5.33mm, vật liệu: Viton | D10: Vòng đệm tròn cao su/O-ring - Kích thước: ID 456.06 x 5.33 mm - Vật liệu: Viton | E10: Vòng đệm tròn cao su/O-ring, KT: ID456.06x5.33mm, vật liệu: Viton | F10: Cái | G10: Cái | H10: 3 | I10: 3 | J10: 2000000 | K10: 0.08 | L10: =H10*J10 -> 6000000 | M10: =L10*(1+K10) -> 6480000 | N10: =K10*L10 -> 480000 | O10: Vật tư/Thiết bị cơ khí | P10: =M10/2 -> 3240000 | Q10: =1.5*(H10*30/365) -> 0.36986301 | R10: =1.5*H10 -> 4.5 | S10: =ROUND(Q10,2) -> 0.37 | T10: =ROUND(R10,2) -> 4.5 | U10: =S10&" sản phẩm/tháng hoặc " &T10& " sản phẩm/năm " -> 0,37 sản phẩm/tháng hoặc 4,5 sản phẩm/năm | W10: 150 ngày | X10: Đơn giá thấp nhất trong các báo giá | Y10: NAK/ Đài Loan | Z10: 4.88.65.560.IND.00.000 | AC10: 0 | AD10: 0 | AE10: 3 | AH10: 3100000 | AI10: Gapi/ Ý | AJ10: 2973000 | AK10: NOK/ Đài Loan | AL10: 2000000 | AM10: NAK/ Đài Loan | AN10: Vòng đệm tròn cao su/O-ring - Kích thước: ID 456.06 x 5.33 mm - Vật liệu: Viton | AO10: Cái | AP10: 3 | AQ10: 4.88.65.560.IND.00.000
A11: 10 | B11: TT_S3_TM__00392 | C11: Vòng đệm tròn cao su/O-ring, Kích thước: ID 53.34 x 5.33 mm | D11: Vòng đệm tròn cao su/O-ring - Kích thước: ID 53.34 x 5.33 mm - Vật liệu: Viton | E11: #N/A | F11: #N/A | G11: Cái | H11: 1 | I11: 1 | J11: 240000 | K11: 0.08 | L11: =H11*J11 -> 240000 | M11: =L11*(1+K11) -> 259200 | N11: =K11*L11 -> 19200 | O11: Vật tư/Thiết bị cơ khí | P11: =M11/2 -> 129600 | Q11: =1.5*(H11*30/365) -> 0.12328767 | R11: =1.5*H11 -> 1.5 | S11: =ROUND(Q11,2) -> 0.12 | T11: =ROUND(R11,2) -> 1.5 | U11: =S11&" sản phẩm/tháng hoặc " &T11& " sản phẩm/năm " -> 0,12 sản phẩm/tháng hoặc 1,5 sản phẩm/năm | W11: 150 ngày | X11: Đơn giá thấp nhất trong các báo giá | Y11: NAK/ Đài Loan | AA11: #N/A | AB11: =VLOOKUP(Z11,'[1]Tra giá ERP'!$A$2:$C$25844,3,0) -> #N/A | AC11: 0 | AD11: 0 | AE11: 1 | AH11: 550000 | AI11: Gapi/ Ý | AJ11: 430000 | AK11: NOK/ Đài Loan | AL11: 240000 | AM11: NAK/ Đài Loan | AN11: Vòng đệm tròn cao su/O-ring - Kích thước: ID 53.34 x 5.33 mm - Vật liệu: Viton | AO11: Cái | AP11: 1
A12: 11 | B12: TT_S3_TM__00393 | C12: Vòng đệm tròn cao su/O-ring, KT: ID46.99x5.33mm, vật liệu: Viton | D12: Vòng đệm tròn cao su/O-ring - Kích thước: ID 46.99 x 5.33 mm - Vật liệu: Viton | E12: Vòng đệm tròn cao su/O-ring, KT: ID46.99x5.33mm, vật liệu: Viton | F12: Cái | G12: Cái | H12: 2 | I12: 2 | J12: 500000 | K12: 0.08 | L12: =H12*J12 -> 1000000 | M12: =L12*(1+K12) -> 1080000 | N12: =K12*L12 -> 80000 | O12: Vật tư/Thiết bị cơ khí | P12: =M12/2 -> 540000 | Q12: =1.5*(H12*30/365) -> 0.24657534 | R12: =1.5*H12 -> 3 | S12: =ROUND(Q12,2) -> 0.25 | T12: =ROUND(R12,2) -> 3 | U12: =S12&" sản phẩm/tháng hoặc " &T12& " sản phẩm/năm " -> 0,25 sản phẩm/tháng hoặc 3 sản phẩm/năm | W12: 150 ngày | X12: Đơn giá thấp nhất trong các báo giá | Y12: NAK/ Đài Loan | Z12: 4.88.65.557.ITA.00.000 | AC12: 0 | AD12: 0 | AE12: 2 | AH12: 540000 | AI12: Gapi/ Ý | AJ12: 780000 | AK12: NOK/ Đài Loan | AL12: 500000 | AM12: NAK/ Đài Loan | AN12: Vòng đệm tròn cao su/O-ring - Kích thước: ID 46.99 x 5.33 mm - Vật liệu: Viton | AO12: Cái | AP12: 2 | AQ12: 4.88.65.557.ITA.00.000
A13: 12 | B13: TT_S3_TM__00394 | C13: Vòng đệm tròn cao su/O-ring, KT: ID 69.44x3.53mm, vật liệu: Viton | D13: Vòng đệm tròn cao su/O-ring - Kích thước: ID 69.44 x 3.53 mm - Vật liệu: Viton | E13: Vòng đệm tròn cao su/O-ring, KT: ID 69.44x3.53mm, vật liệu: Viton | F13: Cái | G13: Cái | H13: 2 | I13: 2 | J13: 250000 | K13: 0.08 | L13: =H13*J13 -> 500000 | M13: =L13*(1+K13) -> 540000 | N13: =K13*L13 -> 40000 | O13: Vật tư/Thiết bị cơ khí | P13: =M13/2 -> 270000 | Q13: =1.5*(H13*30/365) -> 0.24657534 | R13: =1.5*H13 -> 3 | S13: =ROUND(Q13,2) -> 0.25 | T13: =ROUND(R13,2) -> 3 | U13: =S13&" sản phẩm/tháng hoặc " &T13& " sản phẩm/năm " -> 0,25 sản phẩm/tháng hoặc 3 sản phẩm/năm | W13: 150 ngày | X13: Đơn giá thấp nhất trong các báo giá | Y13: NAK/ Đài Loan | Z13: 4.88.65.549.ITA.00.000 | AC13: 0 | AD13: 0 | AE13: 2 | AH13: 312000 | AI13: Gapi/ Ý | AJ13: 280000 | AK13: NOK/ Đài Loan | AL13: 250000 | AM13: NAK/ Đài Loan | AN13: Vòng đệm tròn cao su/O-ring - Kích thước: ID 69.44 x 3.53 mm - Vật liệu: Viton | AO13: Cái | AP13: 2 | AQ13: 4.88.65.549.ITA.00.000
A14: 13 | B14: TT_S3_TM__00395 | C14: Vòng đệm nhựa, rộng: 20mm, dày: 2mm, chất liệu: Teflon | D14: Vòng đệm nhựa - Chiều rộng: 20. mm - Chiều dày: 2 mm - Chất liệu: Teflon | E14: Vòng đệm nhựa, rộng: 20mm, dày: 2mm, chất liệu: Teflon | F14: Mét | G14: Mét | H14: 1.5 | I14: 1.5 | J14: 1000000 | K14: 0.08 | L14: =H14*J14 -> 1500000 | M14: =L14*(1+K14) -> 1620000 | N14: =K14*L14 -> 120000 | O14: Vật tư/Thiết bị cơ khí | P14: =M14/2 -> 810000 | Q14: =1.5*(H14*30/365) -> 0.18493151 | R14: =1.5*H14 -> 2.25 | S14: =ROUND(Q14,2) -> 0.18 | T14: =ROUND(R14,2) -> 2.25 | U14: =S14&" sản phẩm/tháng hoặc " &T14& " sản phẩm/năm " -> 0,18 sản phẩm/tháng hoặc 2,25 sản phẩm/năm | W14: 150 ngày | X14: Đơn giá thấp nhất trong các báo giá | Y14: NAK/ Đài Loan | Z14: 4.90.80.221.IND.00.000 | AC14: 0 | AD14: 0 | AE14: 1.5 | AH14: 1200000 | AI14: Gapi/ Ý | AJ14: 1450000 | AK14: NOK/ Đài Loan | AL14: 1000000 | AM14: NAK/ Đài Loan | AN14: Vòng đệm nhựa - Chiều rộng: 20. mm - Chiều dày: 2 mm - Chất liệu: Teflon | AO14: Mét | AP14: 1.5 | AQ14: 4.90.80.221.IND.00.000
A15: 14 | B15: TT_S3_TM__00531 | C15: Van điện từ/Solenoid valve, Model: 8316P064, 10-250 psi, 110-240 VAC | D15: Van điện từ/Solenoid valve: - Model: 8316P064 - Voltage: 110-240VAC 50Hz, 2W - Inert gas: 10-250 psi Manufacturer: ASCO | E15: Solenoid valve, Model: 8316P064, 10-250 psi, 110-240 VAC | F15: Cái | G15: Cái | H15: 2 | I15: 2 | J15: 37000000 | K15: 0.08 | L15: =H15*J15 -> 74000000 | M15: =L15*(1+K15) -> 79920000 | N15: =K15*L15 -> 5920000 | O15: Vật tư/Thiết bị điện | P15: =M15/2 -> 39960000 | Q15: =1.5*(H15*30/365) -> 0.24657534 | R15: =1.5*H15 -> 3 | S15: =ROUND(Q15,2) -> 0.25 | T15: =ROUND(R15,2) -> 3 | U15: =S15&" sản phẩm/tháng hoặc " &T15& " sản phẩm/năm " -> 0,25 sản phẩm/tháng hoặc 3 sản phẩm/năm | W15: 150 ngày | X15: Đơn giá thấp nhất trong các báo giá | Y15: ASCO/ Singapore | Z15: 5.19.90.184.MEX.00.000 | AA15: 20088000 | AB15: =VLOOKUP(Z15,'[1]Tra giá ERP'!$A$2:$C$25844,3,0) -> Nhập kho vật tư (HĐ:106/2023) theo hóa đơn số 00000025 ngày 23.11.2023 | AC15: 0 | AD15: 0 | AE15: 2 | AG15: Chỉnh sửa tên vật tư trong ERP cho phù với quy tắc chuẩn hóa, đơn vị tính cái | AH15: 37000000 | AI15: ASCO/ Singapore | AJ15: 38000000 | AK15: Asco/ Mỹ | AL15: 41200000 | AM15: ASCO/ Đức | AN15: Cụm van điện từ thường đóng: - Model: 8316P064 - Voltage: 110-240VAC 50Hz, 2W - Inert gas: 10-250 psi Manufacturer: ASCO | AO15: Bộ | AP15: 2 | AQ15: 5.19.90.184.MEX.00.000
A16: 15 | B16: TT_S3_TM__00532 | C16: Van điện từ/ Solenoid valve | D16: Van điện từ/ Solenoid valve: - Model: 8316P066 - Voltage: 110-240VAC 50Hz, 2W - Inert gas: 10-250 psi Manufacturer: ASCO | E16: Solenoid valve, Model: 8316P066, 10-250 psi, 100-240/50-60 Hz/DC | F16: Cái | G16: Cái | H16: 2 | I16: 2 | J16: 14350000 | K16: 0.08 | L16: =H16*J16 -> 28700000 | M16: =L16*(1+K16) -> 30996000 | N16: =K16*L16 -> 2296000 | O16: Vật tư/Thiết bị điện | P16: =M16/2 -> 15498000 | Q16: =1.5*(H16*30/365) -> 0.24657534 | R16: =1.5*H16 -> 3 | S16: =ROUND(Q16,2) -> 0.25 | T16: =ROUND(R16,2) -> 3 | U16: =S16&" sản phẩm/tháng hoặc " &T16& " sản phẩm/năm " -> 0,25 sản phẩm/tháng hoặc 3 sản phẩm/năm | W16: 150 ngày | X16: Đơn giá thấp nhất trong các báo giá | Y16: ASCO/ Singapore | Z16: 5.19.90.215.MEX.99.000 | AA16: 14190000 | AB16: =VLOOKUP(Z16,'[1]Tra giá ERP'!$A$2:$C$25844,3,0) -> Nhập kho vật tư (HĐ: 50/2025) theo hóa đơn số 804 ngày 07.10.2025 | AC16: 0 | AD16: 0 | AE16: 2 | AG16: Chỉnh sửa tên vật tư trong ERP cho phù với quy tắc chuẩn hóa, đơn vị tính cái | AH16: 14350000 | AI16: ASCO/ Singapore | AJ16: 15900000 | AK16: Asco/ Mỹ | AL16: 18000000 | AM16: ASCO/ Đức | AN16: Cụm van điện từ thường mở: - Model: 8316P066 - Voltage: 110-240VAC 50Hz, 2W - Inert gas: 10-250 psi Manufacturer: ASCO | AO16: Bộ | AP16: 2 | AQ16: 5.19.90.215.MEX.99.000
A17: 16 | B17: TT_S3_TM__00800 | C17: Vòng đệm làm kín/ Bonet gasket pos 10 | D17: Vòng đệm làm kín/ Bonet gasket pos 10 (model : BV500 class 600, body 2'', serial no: 24255,24256,24257,24258,24259,24260,24261, 24262 NSX: WEIR hoặc tương đương, | E17: #N/A | F17: #N/A | G17: Cái | H17: 9 | I17: 9 | J17: 124250000 | K17: 0.08 | L17: =H17*J17 -> 1118250000 | M17: =L17*(1+K17) -> 1207710000 | N17: =K17*L17 -> 89460000 | O17: Vật tư/Thiết bị cơ khí | P17: =M17/2 -> 603855000 | Q17: =1.5*(H17*30/365) -> 1.109589 | R17: =1.5*H17 -> 13.5 | S17: =ROUND(Q17,2) -> 1.11 | T17: =ROUND(R17,2) -> 13.5 | U17: =S17&" sản phẩm/tháng hoặc " &T17& " sản phẩm/năm " -> 1,11 sản phẩm/tháng hoặc 13,5 sản phẩm/năm | V17: CO, CQ | W17: 150 ngày | X17: Đơn giá thấp nhất trong các báo giá | Y17: WEIR/ Hàn Quốc | AA17: #N/A | AB17: =VLOOKUP(Z17,'[1]Tra giá ERP'!$A$2:$C$25844,3,0) -> #N/A | AC17: 0 | AD17: 0 | AE17: 9 | AG17: Bản vẽ đính kèm | AH17: 124250000 | AI17: WEIR/ Hàn Quốc | AJ17: 135600000 | AK17: Weir/ Trung Quốc | AL17: 141900000 | AM17: WEIR/ Hàn Quốc | AN17: Vòng đệm làm kín/ Bonet gasket pos 10 (model : BV500 class 600, body 2'', NSX: WEIR hoặc tương đương, serial no: 24255,24256,24257,24258,24259,24260,24261, 24262)/Tấm chèn chi tiết van | AO17: Cái | AP17: 9
A18: 17 | B18: TT_S3_TM__00801 | C18: Vòng đệm làm kín/ Seat gasket pos 11 | D18: Vòng đệm làm kín/ seat gasket pos 11; cho loại van BV500 class 600, body 2", Serial no: 19171,19173,19175,19177,19179,19181,19183, 19185 NSX: WEIR hoặc tương đương | E18: Vòng đệm làm kín/ seat gasket pos 11; cho loại van BV500 class 600, body 2, Serial no: 19171,19173,19175,19177,19179,19181,19183, 19185 | F18: Cái | G18: Cái | H18: 9 | I18: 9 | J18: 137250000 | K18: 0.08 | L18: =H18*J18 -> 1235250000 | M18: =L18*(1+K18) -> 1334070000 | N18: =K18*L18 -> 98820000 | O18: Vật tư/Thiết bị cơ khí | P18: =M18/2 -> 667035000 | Q18: =1.5*(H18*30/365) -> 1.109589 | R18: =1.5*H18 -> 13.5 | S18: =ROUND(Q18,2) -> 1.11 | T18: =ROUND(R18,2) -> 13.5 | U18: =S18&" sản phẩm/tháng hoặc " &T18& " sản phẩm/năm " -> 1,11 sản phẩm/tháng hoặc 13,5 sản phẩm/năm | V18: CO, CQ | W18: 150 ngày | X18: Đơn giá thấp nhất trong các báo giá | Y18: WEIR/ Hàn Quốc | Z18: 5.04.01.081.KOR.00.000 | AA18: 12291700 | AB18: =VLOOKUP(Z18,'[1]Tra giá ERP'!$A$2:$C$25844,3,0) -> Nhập kho vật tư (HĐ:46/2022) theo hóa đơn số 68, 69 ngày 13.10.2022 | AC18: 0 | AD18: 0 | AE18: 9 | AG18: Bản vẽ đính kèm | AH18: 143000000 | AI18: WEIR/ Hàn Quốc | AJ18: 155000000 | AK18: Weir/ Trung Quốc | AL18: 137250000 | AM18: WEIR/ Hàn Quốc | AN18: Vòng đệm làm kín/ Seat gasket pos 11 (model : BV500 class 600, body 2'', NSX: WEIR hoặc tương đương, serial no: 19172,19174,19176,19178,19180,19182,19184, 19186)/Tấm chèn chi tiết van | AO18: Cái | AP18: 9 | AQ18: 5.04.01.081.KOR.00.000
A19: 18 | B19: TT_S3_TM__00802 | C19: Chèn làm kín/ Packing grafoil pos 12 | D19: Chèn làm kín/ packing grafoil pos 12; sử dụng cho loại van BV500 class 600, body 2", serial no: 19171,19173,19175,19177,19179,19181,19183, 19185 NSX: WEIR hoặc tương đương | E19: #N/A | F19: #N/A | G19: Bộ | H19: 9 | I19: 9 | J19: 131250000 | K19: 0.08 | L19: =H19*J19 -> 1181250000 | M19: =L19*(1+K19) -> 1275750000 | N19: =K19*L19 -> 94500000 | O19: Vật tư/Thiết bị cơ khí | P19: =M19/2 -> 637875000 | Q19: =1.5*(H19*30/365) -> 1.109589 | R19: =1.5*H19 -> 13.5 | S19: =ROUND(Q19,2) -> 1.11 | T19: =ROUND(R19,2) -> 13.5 | U19: =S19&" sản phẩm/tháng hoặc " &T19& " sản phẩm/năm " -> 1,11 sản phẩm/tháng hoặc 13,5 sản phẩm/năm | V19: CO, CQ | W19: 150 ngày | X19: Đơn giá thấp nhất trong các báo giá | Y19: WEIR/ Hàn Quốc | Z19: 5.04.01.185.KOR.00.000 | AA19: #N/A | AB19: =VLOOKUP(Z19,'[1]Tra giá ERP'!$A$2:$C$25844,3,0) -> #N/A | AC19: 0 | AD19: 0 | AE19: 9 | AG19: Bản vẽ đính kèm | AH19: 132000000 | AI19: WEIR/ Hàn Quốc | AJ19: 131250000 | AK19: Weir/ Trung Quốc | AL19: 150000000 | AM19: Emerson/ Mỹ | AN19: Chèn làm kín/ Packing grafoil pos 12 (model : BV500 class 600, body 2'', NSX: WEIR hoặc tương đương, serial no: 19172,19174,19176,19178,19180,19182,19184, 19186) | AO19: Bộ | AP19: 9 | AQ19: 5.04.01.185.KOR.00.000
A20: 19 | B20: TT_S3_TM__01286 | C20: Tấm đệm làm kín Tombo 1995, sizes: 2mm x 1S (1270×1270mm) | D20: Tấm đệm làm kín Tombo 1995, sizes: 2mm x 1S (1270×1270mm) | E20: Tấm đệm làm kín Tombo 1995, sizes: 2mm x 1S (1270×1270mm) | F20: Tấm | G20: Tấm | H20: =2+1 -> 3 | I20: 2 | J20: 49954909 | K20: 0.08 | L20: =H20*J20 -> 1.4986473e+08 | M20: =L20*(1+K20) -> 1.6185391e+08 | N20: =K20*L20 -> 11989178 | O20: Vật tư/Thiết bị cơ khí | P20: =M20/2 -> 80926953 | Q20: =1.5*(H20*30/365) -> 0.36986301 | R20: =1.5*H20 -> 4.5 | S20: =ROUND(Q20,2) -> 0.37 | T20: =ROUND(R20,2) -> 4.5 | U20: =S20&" sản phẩm/tháng hoặc " &T20& " sản phẩm/năm " -> 0,37 sản phẩm/tháng hoặc 4,5 sản phẩm/năm | V20: CO, CQ | W20: 150 ngày | X20: Đơn giá thấp nhất trong các báo giá | Y20: NICHIAS/ Nhật Bản | Z20: 4.86.10.128.JPN.00.000 | AA20: 41629091 | AB20: =VLOOKUP(Z20,'[1]Tra giá ERP'!$A$2:$C$25844,3,0) -> Nhập kho vật tư (HĐ:73/2023) theo hóa đơn số 157 ngày 30.08.2023 | AC20: 0 | AD20: 0 | AE20: 2 | AH20: 51980000 | AI20: NICHIAS/ Nhật Bản | AJ20: 55000000 | AK20: Klinger/ Đức | AL20: 49954909 | AM20: Song Nguyên/ Việt Nam | AN20: Tấm đệm làm kín Tombo 1995 - Sizes: 2mm x 1S (1270×1270mm) | AO20: Tấm | AP20: 2 | AQ20: 4.86.10.128.JPN.00.000 | AR20: Tăng thêm 1 tấm chuyển từ gói anh minh sang
A21: 20 | B21: TT_S3_TM__01489 | C21: Floating Labyrinth Seals/ chèn dầu ổ trục động cơ | D21: Floating Labyrinth Seals/ chèn dầu ổ trục động cơ - Dimensions: D: 200mm, d1: 220mm, d2:230mm, d3: 222mm, d4: 232mm, garter spring: ∅5x1, length: 651mm - Material: Plyimide - Color: Amber NSX: RENK hoặc tương đương | E21: #N/A | F21: #N/A | G21: Bộ | H21: 2 | I21: 2 | J21: 10000000 | K21: 0.08 | L21: =H21*J21 -> 20000000 | M21: =L21*(1+K21) -> 21600000 | N21: =K21*L21 -> 1600000 | O21: Vật tư/Thiết bị cơ khí | P21: =M21/2 -> 10800000 | Q21: =1.5*(H21*30/365) -> 0.24657534 | R21: =1.5*H21 -> 3 | S21: =ROUND(Q21,2) -> 0.25 | T21: =ROUND(R21,2) -> 3 | U21: =S21&" sản phẩm/tháng hoặc " &T21& " sản phẩm/năm " -> 0,25 sản phẩm/tháng hoặc 3 sản phẩm/năm | W21: 150 ngày | X21: Đơn giá thấp nhất trong các báo giá | Y21: RENK/ Trung Quốc | Z21: Chưa có mã VT | AA21: #N/A | AB21: =VLOOKUP(Z21,'[1]Tra giá ERP'!$A$2:$C$25844,3,0) -> #N/A | AC21: 0 | AD21: 0 | AE21: 2 | AG21: Tài liệu định kèm | AH21: 19200000 | AI21: RENK/ Trung Quốc | AJ21: 10000000 | AK21: RENK/ Trung Quốc | AL21: 15400000 | AM21: RENK/ Trung Quốc | AN21: Floating Labyrinth Seals/ chèn dầu ổ trục động cơ - Dimensions: D: 200mm, d1: 220mm, d2:230mm, d3: 222mm, d4: 232mm, garter spring: ∅5x1, length: 651mm - Material: Plyimide - Color: Amber | AO21: Bộ | AP21: 2 | AQ21: Chưa có mã VT
A22: 21 | B22: TT_S3_TM__01741 | C22: Nhựa tấm teflon (PTFE tấm), KT: 1000mmx1000mmx04mm | D22: Nhựa tấm teflon (PTFE tấm), KT: 1000mmx1000mmx04mm | E22: #N/A | F22: #N/A | G22: Tấm | H22: =1+1 -> 2 | I22: 1 | J22: 18372000 | K22: 0.08 | L22: =H22*J22 -> 36744000 | M22: =L22*(1+K22) -> 39683520 | N22: =K22*L22 -> 2939520 | O22: Vật tư/Thiết bị cơ khí | P22: =M22/2 -> 19841760 | Q22: =1.5*(H22*30/365) -> 0.24657534 | R22: =1.5*H22 -> 3 | S22: =ROUND(Q22,2) -> 0.25 | T22: =ROUND(R22,2) -> 3 | U22: =S22&" sản phẩm/tháng hoặc " &T22& " sản phẩm/năm " -> 0,25 sản phẩm/tháng hoặc 3 sản phẩm/năm | W22: 150 ngày | X22: Đơn giá thấp nhất trong các báo giá | Y22: YUANYU/ Trung Quốc | Z22: Chưa có mã VT | AA22: #N/A | AB22: =VLOOKUP(Z22,'[1]Tra giá ERP'!$A$2:$C$25844,3,0) -> #N/A | AC22: 0 | AD22: 0 | AE22: 1 | AH22: 22000000 | AI22: Wenzhou/ Trung Quốc | AJ22: 18372000 | AK22: YUANYU/ Trung Quốc | AL22: 28340000 | AM22: Acetal/ Mỹ | AN22: Tấm Teflon kích thước 1000x1000x4mm | AO22: Tấm | AP22: 1 | AQ22: Chưa có mã VT | AR22: Tăng thêm 1 tấm chuyển từ gói anh minh sang
A23: 22 | B23: TT_S3_TM__02051 | C23: Thép tấm hardox 500, KT: 1000mmx3000mmx6mm | D23: Thép tấm hardox 500, KT: 1000mmx3000mmx6mm | E23: Thép tấm hardox 500, KT: 1000mmx3000mmx6mm | F23: Tấm | G23: Tấm | H23: 1 | I23: 1 | J23: 18500000 | K23: 0.08 | L23: =H23*J23 -> 18500000 | M23: =L23*(1+K23) -> 19980000 | N23: =K23*L23 -> 1480000 | O23: Vật tư/Thiết bị cơ khí | P23: =M23/2 -> 9990000 | Q23: =1.5*(H23*30/365) -> 0.12328767 | R23: =1.5*H23 -> 1.5 | S23: =ROUND(Q23,2) -> 0.12 | T23: =ROUND(R23,2) -> 1.5 | U23: =S23&" sản phẩm/tháng hoặc " &T23& " sản phẩm/năm " -> 0,12 sản phẩm/tháng hoặc 1,5 sản phẩm/năm | W23: 150 ngày | X23: Đơn giá thấp nhất trong các báo giá | Y23: Baosteel/ Trung Quốc | Z23: 2.44.01.018.SWE.00.000 | AC23: 0 | AD23: 0 | AE23: 1 | AH23: 18500000 | AI23: Baosteel/ Trung Quốc | AJ23: 29450000 | AK23: SABB/ Thụy Điển | AL23: 25000000 | AM23: Quantong Metal/ Trung Quốc | AN23: Thép tấm hardox 500, kích thước: 1000x3000x6mm (ngang x dài x dày) | AO23: Tấm | AP23: 1 | AQ23: 2.44.01.018.SWE.00.000
A24: 23 | B24: TT_S3_TM__02068 | C24: Module Analog in/out, Mác mã: XBF-AH04A, Số kênh ngõ vào/ ra tương tự: 2 kênh (-10-10 VDC, 0-20 mA) | D24: Module Analog In/Out XBF-AH04A LS - Maker: LS - Model: XBF-AH04A - Type: Module Analog In/Out - Analog Input: 2 Kênh (-10-10VDC, 0-20mA) - Analog output: 2 Kênh (-10-10VDC, 0-20mA) | E24: Module Analog in/out, Mác mã: XBF-AH04A, Số kênh ngõ vào/ ra tương tự: 2 kênh (-10-10 VDC, 0-20 mA) | F24: Cái | G24: Cái | H24: 1 | I24: 1 | J24: 8700000 | K24: 0.08 | L24: =H24*J24 -> 8700000 | M24: =L24*(1+K24) -> 9396000 | N24: =K24*L24 -> 696000 | O24: Vật tư/Thiết bị điện | P24: =M24/2 -> 4698000 | Q24: =1.5*(H24*30/365) -> 0.12328767 | R24: =1.5*H24 -> 1.5 | S24: =ROUND(Q24,2) -> 0.12 | T24: =ROUND(R24,2) -> 1.5 | U24: =S24&" sản phẩm/tháng hoặc " &T24& " sản phẩm/năm " -> 0,12 sản phẩm/tháng hoặc 1,5 sản phẩm/năm | W24: 150 ngày | X24: Đơn giá thấp nhất trong các báo giá | Y24: LS/ Hàn Quốc | Z24: 3.82.63.043.KOR.00.000 | AA24: 8700000 | AB24: =VLOOKUP(Z24,'[1]Tra giá ERP'!$A$2:$C$25844,3,0) -> Nhập kho vật tư (QĐ: 375/2025) theo hóa đơn số 23 ngày 31.03.2025 | AC24: 0 | AD24: 0 | AE24: 1 | AG24: Điều chỉnh đơn vị theo ERP | AH24: 11000000 | AI24: LS/ Hàn Quốc | AJ24: 8700000 | AK24: LS/ Hàn Quốc | AL24: 14300000 | AM24: LS/ Hàn Quốc | AN24: Module Analog In/Out XBF-AH04A LS - Maker: LS - Model: XBF-AH04A - Type: Module Analog In/Out - Analog Input: 2 Kênh (-10-10VDC, 0-20mA) - Analog output: 2 Kênh (-10-10VDC, 0-20mA) | AO24: Bộ | AP24: 1 | AQ24: 3.82.63.043.KOR.00.000
A25: 24 | B25: TT_S3_TM__02069 | C25: Phớt chắn dầu /Oil seal, KT: 60x70x7mm | D25: Phớt chắn dầu / Oil seal: - Kích thước: 60x70x7 - Loại: K21 - Vật liệu: NBR - Order code: K21-060/7 - Nhiệt độ hoạt động: 105 oC - Áp suất tối đa: 150 bar - Nhà sản xuất: Kastas | E25: Oil seal, KT: 60x70x7mm | F25: Cái | G25: Cái | H25: 10 | I25: 10 | J25: 2700000 | K25: 0.08 | L25: =H25*J25 -> 27000000 | M25: =L25*(1+K25) -> 29160000 | N25: =K25*L25 -> 2160000 | O25: Vật tư/Thiết bị cơ khí | P25: =M25/2 -> 14580000 | Q25: =1.5*(H25*30/365) -> 1.2328767 | R25: =1.5*H25 -> 15 | S25: =ROUND(Q25,2) -> 1.23 | T25: =ROUND(R25,2) -> 15 | U25: =S25&" sản phẩm/tháng hoặc " &T25& " sản phẩm/năm " -> 1,23 sản phẩm/tháng hoặc 15 sản phẩm/năm | W25: 150 ngày | X25: Đơn giá thấp nhất trong các báo giá | Y25: Katas/ Trung Quốc | Z25: 4.88.65.229.TUR.00.000 | AA25: 313000 | AB25: =VLOOKUP(Z25,'[1]Tra giá ERP'!$A$2:$C$25844,3,0) -> Nhập kho vật tư (HĐ: 34/2025) theo hóa đơn số 00000119 ngày 01.08.2025 | AC25: 0 | AD25: 0 | AE25: 10 | AG25: Chỉnh sửa lại tên ERP theo quy tắc chuẩn hóa | AH25: 4123000 | AI25: Katas/ Đức | AJ25: 2700000 | AK25: Katas/ Trung Quốc | AL25: 3200000 | AM25: NAK/ Đài Loan | AN25: Phớt chắn dầu / Oil seal: - Kích thước: 60x70x7 - Loại: K21 - Vật liệu: NBR - Order code: K21-060/7 - Nhiệt độ hoạt động: 105 oC - Áp suất tối đa: 150 bar - Nhà sản xuất: Kastas | AO25: Cái | AP25: 10 | AQ25: 4.88.65.229.TUR.00.000
A26: 25 | B26: TT_S3_TM__02070 | C26: Phớt piston /Piston seal, KT: 85x100x9mm | D26: Phớt piston / Piston seal - Kích thước: 85x100x9 - Loại: K21 - Vật liệu: NBR - Order code: K21-085/8 - Nhiệt độ hoạt động: 105°C - Áp suất tối đa: 150 bar - Nhà sản xuất: Kastas | E26: Piston seal, KT: 85x100x9mm | F26: Cái | G26: Cái | H26: 10 | I26: 10 | J26: 2500000 | K26: 0.08 | L26: =H26*J26 -> 25000000 | M26: =L26*(1+K26) -> 27000000 | N26: =K26*L26 -> 2000000 | O26: Vật tư/Thiết bị cơ khí | P26: =M26/2 -> 13500000 | Q26: =1.5*(H26*30/365) -> 1.2328767 | R26: =1.5*H26 -> 15 | S26: =ROUND(Q26,2) -> 1.23 | T26: =ROUND(R26,2) -> 15 | U26: =S26&" sản phẩm/tháng hoặc " &T26& " sản phẩm/năm " -> 1,23 sản phẩm/tháng hoặc 15 sản phẩm/năm | W26: 150 ngày | X26: Đơn giá thấp nhất trong các báo giá | Y26: Katas/ Trung Quốc | Z26: 4.88.65.230.TUR.00.000 | AA26: 380000 | AB26: =VLOOKUP(Z26,'[1]Tra giá ERP'!$A$2:$C$25844,3,0) -> Nhập kho vật tư (HĐ: 34/2025) theo hóa đơn số 00000119 ngày 01.08.2025 | AC26: 0 | AD26: 0 | AE26: 10 | AG26: Chỉnh sửa lại tên ERP theo quy tắc chuẩn hóa | AH26: 3120000 | AI26: Katas/ Đức | AJ26: 2500000 | AK26: Katas/ Trung Quốc | AL26: 2980000 | AM26: NAK/ Đài Loan | AN26: Phớt piston / Piston seal - Kích thước: 85x100x9 - Loại: K21 - Vật liệu: NBR - Order code: K21-085/8 - Nhiệt độ hoạt động: 105°C - Áp suất tối đa: 150 bar - Nhà sản xuất: Kastas | AO26: Cái | AP26: 10 | AQ26: 4.88.65.230.TUR.00.000
A27: 26 | B27: TT_S3_TM__02071 | C27: Phớt chắn bụi, KT: 60x70.6x5.3x7, Vật liệu: NBR | D27: Phớt chắn bụi / Wiper seal: - Kích thước: 60x70,6x5,3x7 - Loại: K06 - Vật liệu: NBR - Order code: K06-060 - Nhiệt độ hoạt động: 105°C - Nhà sản xuất: Kastas | E27: Phớt chắn bụi, KT: 60x70.6x5.3x7, Vật liệu: NBR | F27: Cái | G27: Cái | H27: 5 | I27: 5 | J27: 450000 | K27: 0.08 | L27: =H27*J27 -> 2250000 | M27: =L27*(1+K27) -> 2430000 | N27: =K27*L27 -> 180000 | O27: Vật tư/Thiết bị cơ khí | P27: =M27/2 -> 1215000 | Q27: =1.5*(H27*30/365) -> 0.61643836 | R27: =1.5*H27 -> 7.5 | S27: =ROUND(Q27,2) -> 0.62 | T27: =ROUND(R27,2) -> 7.5 | U27: =S27&" sản phẩm/tháng hoặc " &T27& " sản phẩm/năm " -> 0,62 sản phẩm/tháng hoặc 7,5 sản phẩm/năm | W27: 150 ngày | X27: Đơn giá thấp nhất trong các báo giá | Y27: Katas/ Trung Quốc | Z27: 4.88.65.231.TUR.00.000 | AA27: 285000 | AB27: =VLOOKUP(Z27,'[1]Tra giá ERP'!$A$2:$C$25844,3,0) -> Nhập kho vật tư (HĐ: 34/2025) theo hóa đơn số 00000119 ngày 01.08.2025 | AC27: 0 | AD27: 0 | AE27: 5 | AH27: 1700000 | AI27: Katas/ Đức | AJ27: 600000 | AK27: Katas/ Trung Quốc | AL27: 450000 | AM27: Katas/ Trung Quốc | AN27: Phớt chắn bụi / Wiper seal: - Kích thước: 60x70,6x5,3x7 - Loại: K06 - Vật liệu: NBR - Order code: K06-060 - Nhiệt độ hoạt động: 105°C - Nhà sản xuất: Kastas | AO27: Cái | AP27: 5 | AQ27: 4.88.65.231.TUR.00.000
A28: 27 | B28: TT_S3_TM__02072 | C28: Vòng đệm KT: ID60xOD70x2mm; Vật liệu: Teflon | D28: Vòng đệm - Kích thước: ID60 x OD70 x 2 - Vật liệu: Teflon | E28: Vòng đệm KT: ID60xOD70x2mm; Vật liệu: Teflon | F28: Bộ | G28: Cái | H28: 5 | I28: 5 | J28: 1675000 | K28: 0.08 | L28: =H28*J28 -> 8375000 | M28: =L28*(1+K28) -> 9045000 | N28: =K28*L28 -> 670000 | O28: Vật tư/Thiết bị cơ khí | P28: =M28/2 -> 4522500 | Q28: =1.5*(H28*30/365) -> 0.61643836 | R28: =1.5*H28 -> 7.5 | S28: =ROUND(Q28,2) -> 0.62 | T28: =ROUND(R28,2) -> 7.5 | U28: =S28&" sản phẩm/tháng hoặc " &T28& " sản phẩm/năm " -> 0,62 sản phẩm/tháng hoặc 7,5 sản phẩm/năm | W28: 150 ngày | X28: Đơn giá thấp nhất trong các báo giá | Y28: NOK/ Đài Loan | Z28: 4.90.80.060.IND.00.000 | AA28: 100000 | AB28: =VLOOKUP(Z28,'[1]Tra giá ERP'!$A$2:$C$25844,3,0) -> Nhập kho vật tư (HĐ: 16/2022) theo hóa đơn số 0000448 ngày 29.03.2022 | AC28: 0 | AD28: 0 | AE28: 5 | AG28: Chỉnh sửa lại đơn vị tính trong ERP thành cái | AH28: 1899000 | AI28: Katas/ Đức | AJ28: 2034000 | AK28: NOK/ Đài Loan | AL28: 1675000 | AM28: NOK/ Đài Loan | AN28: Vòng đệm - Kích thước: ID60 x OD70 x 2 - Vật liệu: Teflon | AO28: Cái | AP28: 5 | AQ28: 4.90.80.060.IND.00.000
A29: 28 | B29: TT_S3_TM__02097 | C29: Tếch chèn PTFE AWC 1724 | D29: Tếch chèn PTFE AWC 1724 trắng 8mm x 8mm (5/16" x 5/16"), 5lbs/hộp | E29: #N/A | F29: #N/A | G29: Hộp | H29: 0.5 | I29: 0.5 | J29: 3400000 | K29: 0.08 | L29: =H29*J29 -> 1700000 | M29: =L29*(1+K29) -> 1836000 | N29: =K29*L29 -> 136000 | O29: Vật tư/Thiết bị cơ khí | P29: =M29/2 -> 918000 | Q29: =1.5*(H29*30/365) -> 0.061643836 | R29: =1.5*H29 -> 0.75 | S29: =ROUND(Q29,2) -> 0.06 | T29: =ROUND(R29,2) -> 0.75 | U29: =S29&" sản phẩm/tháng hoặc " &T29& " sản phẩm/năm " -> 0,06 sản phẩm/tháng hoặc 0,75 sản phẩm/năm | W29: 150 ngày | X29: Đơn giá thấp nhất trong các báo giá | Y29: Chesterton/ Mỹ | AA29: #N/A | AB29: =VLOOKUP(Z29,'[1]Tra giá ERP'!$A$2:$C$25844,3,0) -> #N/A | AC29: 0 | AD29: 0 | AE29: 0.5 | AH29: 4100000 | AI29: Chesterton/ Mỹ | AJ29: 3650000 | AK29: Chesterton/ Mỹ | AL29: 3400000 | AM29: Chesterton/ Mỹ | AN29: Tếch chèn PTFE AWC 1724 trắng 8mm x 8mm (5/16" x 5/16"), 5lbs/hộp | AO29: hộp | AP29: 0.5
A30: 29 | B30: TT_S3_TM__02207 | C30: Bộ chỉnh áp điều chỉnh khí nén (Air regulator) | D30: Bộ chỉnh áp điều chỉnh khí nén (Air regulator) Model: YT-200BN221 Air Connection: NPT 1/4 Adjust Range: 0 - 8.4 bar Gauges: one Max. Supply: 1.7 Mpa Bao gồm đồng hồ NSX: Rotork YTC | E30: Bộ chỉnh áp điều chỉnh khí nén - Air regulator; Air Connection: NPT 1/4; Adjust Range: 0 - 8.4 bar; Gauges: one; Max.Supply: 1.7Mpa; Model: YT-200BN221 | F30: Cái | G30: Cái | H30: 6 | I30: 6 | J30: 3420000 | K30: 0.08 | L30: =H30*J30 -> 20520000 | M30: =L30*(1+K30) -> 22161600 | N30: =K30*L30 -> 1641600 | O30: Vật tư/Thiết bị cơ khí | P30: =M30/2 -> 11080800 | Q30: =1.5*(H30*30/365) -> 0.73972603 | R30: =1.5*H30 -> 9 | S30: =ROUND(Q30,2) -> 0.74 | T30: =ROUND(R30,2) -> 9 | U30: =S30&" sản phẩm/tháng hoặc " &T30& " sản phẩm/năm " -> 0,74 sản phẩm/tháng hoặc 9 sản phẩm/năm | W30: 150 ngày | X30: Đơn giá thấp nhất trong các báo giá | Y30: Rotork YTC/ Hàn Quốc | Z30: 5.33.70.820.KOR.00.000 | AA30: 2850000 | AB30: =VLOOKUP(Z30,'[1]Tra giá ERP'!$A$2:$C$25844,3,0) -> Nhập kho vật tư (HĐ:130/2021) theo hóa đơn số 0000024,25 ngày 24.05.2022 | AC30: 0 | AD30: 0 | AE30: 6 | AG30: Bổ sung nhà sản xuất Rotork YTC, điều chỉnh đơn vị tính cái theo ERP | AH30: 3420000 | AI30: Rotork YTC/ Hàn Quốc | AJ30: 3500000 | AK30: Rotork YTC/ Hàn Quốc | AL30: 4560000 | AM30: Rotork YTC/ Hàn Quốc | AN30: Bộ điều áp (Air regulator) Model: YT-200BN221 Air Connection: NPT 1/4 Adjust Range: 0 - 8.4 bar Gauges: one Max. Supply: 1.7 Mpa Bao gồm đồng hồ | AO30: Bộ | AP30: 6 | AQ30: 5.33.70.820.KOR.00.000
A31: 30 | B31: TT_S3_TM__02245 | C31: Bộ điều chỉnh khí nén, Mã: LFR-3/4-D-MAXI-A | D31: Bộ điều áp (Regulator) Model: LFR-3/4-D-MAXI-A Order code: 159636; Type: Filter regulator with pressure gauge; Operating pressure: 2 ~ 12 bar; Grade of filtration: 40 µm; Connection: G ¾ inch NSX : Festo | E31: Bộ điều chỉnh khí nén, Mã: LFR-3/4-D-MAXI-A | F31: Bộ | G31: Bộ | H31: 6 | I31: 6 | J31: 21500000 | K31: 0.08 | L31: =H31*J31 -> 129000000 | M31: =L31*(1+K31) -> 139320000 | N31: =K31*L31 -> 10320000 | O31: Vật tư/Thiết bị cơ khí | P31: =M31/2 -> 69660000 | Q31: =1.5*(H31*30/365) -> 0.73972603 | R31: =1.5*H31 -> 9 | S31: =ROUND(Q31,2) -> 0.74 | T31: =ROUND(R31,2) -> 9 | U31: =S31&" sản phẩm/tháng hoặc " &T31& " sản phẩm/năm " -> 0,74 sản phẩm/tháng hoặc 9 sản phẩm/năm | W31: 150 ngày | X31: Đơn giá thấp nhất trong các báo giá | Y31: Rotork YTC/ Hàn Quốc | Z31: 5.33.70.911.HUN.99.000 | AC31: 0 | AD31: 0 | AE31: 6 | AG31: Bổ sung nhà sản xuất Festo | AH31: 21500000 | AI31: Rotork YTC/ Hàn Quốc | AJ31: 33400000 | AK31: Rotork YTC/ Hàn Quốc | AL31: 25000000 | AM31: Rotork YTC/ Hàn Quốc | AN31: Bộ điều áp (Regulator) Model: LFR-3/4-D-MAXI-A Order code: 159636; Type: Filter regulator with pressure gauge; Operating pressure: 2 ~ 12 bar; Grade of filtration: 40 µm; Connection: G ¾ inch | AO31: Bộ | AP31: 6 | AQ31: 5.33.70.911.HUN.99.000
A32: 31 | B32: TT_S3_TM__02294 | C32: Van giảm âm hệ thống khí nén chống tắt than Silo | D32: Van giảm âm hệ thống khí nén chống tắt than Silo '- Mã: AMTE-M-H-G12, Part number: 1206625, áp suất: 0-10bar, Đầu kết nối: G1/2, Vật liệu: Bronze. - NSX: Festo | E32: Van giảm âm hệ thống khí nén chống tắt than Silo-Pneumatic Silencer, Model: AMTE-M-H-G12, Part number: 1206625, Pressure: 0-10bar, Thread connection: G1/2, Material: Bronze | F32: Cái | G32: Cái | H32: 12 | I32: 12 | J32: 882000 | K32: 0.08 | L32: =H32*J32 -> 10584000 | M32: =L32*(1+K32) -> 11430720 | N32: =K32*L32 -> 846720 | O32: Vật tư/Thiết bị cơ khí | P32: =M32/2 -> 5715360 | Q32: =1.5*(H32*30/365) -> 1.4794521 | R32: =1.5*H32 -> 18 | S32: =ROUND(Q32,2) -> 1.48 | T32: =ROUND(R32,2) -> 18 | U32: =S32&" sản phẩm/tháng hoặc " &T32& " sản phẩm/năm " -> 1,48 sản phẩm/tháng hoặc 18 sản phẩm/năm | W32: 150 ngày | X32: Đơn giá thấp nhất trong các báo giá | Y32: Festo/ Trung Quốc | Z32: 5.19.90.012.GER.00.000 | AA32: 735000 | AB32: =VLOOKUP(Z32,'[1]Tra giá ERP'!$A$2:$C$25844,3,0) -> Nhập kho vật tư (HĐ:222) theo hóa đơn số 0000274 ngày 24.02.2021 | AC32: 0 | AD32: 0 | AE32: 12 | AG32: Điều chỉnh tên, TSKT theo ERP | AH32: 1200000 | AI32: Festo/ Trung Quốc | AJ32: 910000 | AK32: Festo/ Trung Quốc | AL32: 882000 | AM32: Festo/ Trung Quốc | AN32: Bộ giảm thanh khí nén/Pneumatic Silencer: - Model: AMTE-M-H-G12 - Part number: 1206625 - Pressure: 0-10bar - Thread connection: G ½ - Material: Bronze - Maker: Festo | AO32: Cái | AP32: 12 | AQ32: 5.19.90.012.GER.00.000
A33: 32 | B33: TT_S3_TM__02430 | C33: Cao su tấm không bố | D33: Cao su tấm không bố, dày 10mm, kích thước 800x1000mm | E33: #N/A | F33: #N/A | G33: Tấm | H33: 1 | I33: 1 | J33: 6700000 | K33: 0.08 | L33: =H33*J33 -> 6700000 | M33: =L33*(1+K33) -> 7236000 | N33: =K33*L33 -> 536000 | O33: Vật tư/Thiết bị cơ khí | P33: =M33/2 -> 3618000 | Q33: =1.5*(H33*30/365) -> 0.12328767 | R33: =1.5*H33 -> 1.5 | S33: =ROUND(Q33,2) -> 0.12 | T33: =ROUND(R33,2) -> 1.5 | U33: =S33&" sản phẩm/tháng hoặc " &T33& " sản phẩm/năm " -> 0,12 sản phẩm/tháng hoặc 1,5 sản phẩm/năm | W33: 150 ngày | X33: Đơn giá thấp nhất trong các báo giá | Y33: Tâm Thiên Phú/ Việt Nam | AA33: #N/A | AB33: =VLOOKUP(Z33,'[1]Tra giá ERP'!$A$2:$C$25844,3,0) -> #N/A | AC33: 0 | AD33: 0 | AE33: 1 | AH33: 7450000 | AI33: Khánh Đạt/ Việt Nam | AJ33: 8000000 | AK33: Cao su A&T/ Việt Nam | AL33: 6700000 | AM33: Tâm Thiên Phú/ Việt Nam | AN33: Cao su tấm không bố, dày 10mm, kích thước 800x1000mm | AO33: Tấm | AP33: 1
A34: 33 | B34: TT_S3_TM__02478 | C34: Bạc đạn | D34: Bạc đạn 6205-2Z/C3 Đường kính trong (d): 25 mm Đường kính ngoài (D): 52 mm Độ dày (B): 15 mm | E34: Bạc đạn 6205-2Z/C3 | F34: Vòng | G34: Vòng | H34: 5 | I34: 5 | J34: 820000 | K34: 0.08 | L34: =H34*J34 -> 4100000 | M34: =L34*(1+K34) -> 4428000 | N34: =K34*L34 -> 328000 | O34: Vật tư/Thiết bị cơ khí | P34: =M34/2 -> 2214000 | Q34: =1.5*(H34*30/365) -> 0.61643836 | R34: =1.5*H34 -> 7.5 | S34: =ROUND(Q34,2) -> 0.62 | T34: =ROUND(R34,2) -> 7.5 | U34: =S34&" sản phẩm/tháng hoặc " &T34& " sản phẩm/năm " -> 0,62 sản phẩm/tháng hoặc 7,5 sản phẩm/năm | W34: 150 ngày | X34: Đơn giá thấp nhất trong các báo giá | Y34: SKF/ Đức | Z34: 5.01.34.206.FRA.00.000 | AA34: 122000 | AB34: =VLOOKUP(Z34,'[1]Tra giá ERP'!$A$2:$C$25844,3,0) -> Nhập kho Bạc đạn (HĐ:223) theo hóa đơn số 0000792 ngày 31.12.2020 ngày 23.12.2020 (phiếu sai) | AC34: 0 | AD34: 0 | AE34: 5 | AG34: Điều chỉnh tên, TSKT theo ERP | AH34: 955000 | AI34: SKF/ Pháp | AJ34: 1100000 | AK34: SKF/ Malaysia | AL34: 820000 | AM34: SKF/ Đức | AN34: vòng bi 6205-2Z/C3 | AO34: Cái | AP34: 5 | AQ34: 5.01.34.206.FRA.00.000
A35: 34 | B35: TT_S3_TM__02479 | C35: Phớt chắn bụi V-ring VA-30 | D35: Thông số kỹ thuật: V-ring VA-30, d=27, A=4.7, B=7.5mm Loại phớt: V-ring | E35: Phớt chắn bụi V-ring VA-30, d=27, A=4.7, B=7.5mm | F35: Cái | G35: Cái | H35: 5 | I35: 5 | J35: 560000 | K35: 0.08 | L35: =H35*J35 -> 2800000 | M35: =L35*(1+K35) -> 3024000 | N35: =K35*L35 -> 224000 | O35: Vật tư/Thiết bị cơ khí | P35: =M35/2 -> 1512000 | Q35: =1.5*(H35*30/365) -> 0.61643836 | R35: =1.5*H35 -> 7.5 | S35: =ROUND(Q35,2) -> 0.62 | T35: =ROUND(R35,2) -> 7.5 | U35: =S35&" sản phẩm/tháng hoặc " &T35& " sản phẩm/năm " -> 0,62 sản phẩm/tháng hoặc 7,5 sản phẩm/năm | W35: 150 ngày | X35: Đơn giá thấp nhất trong các báo giá | Y35: SKF/ Pháp | Z35: 4.88.65.141.TPE.00.000 | AA35: 30000 | AB35: =VLOOKUP(Z35,'[1]Tra giá ERP'!$A$2:$C$25844,3,0) -> Nhập kho vật tư (HĐ:62/2023) theo hóa đơn số 00000084 ngày 17.08.2023 | AC35: 0 | AD35: 0 | AE35: 5 | AG35: Điều chỉnh tên, TSKT theo ERP | AH35: 982000 | AI35: SKF/ Trung Quốc | AJ35: 780000 | AK35: SKF/ Malaysia | AL35: 560000 | AM35: SKF/ Pháp | AN35: Phớt chắn bụi VA-030 | AO35: Cái | AP35: 5 | AQ35: 4.88.65.141.TPE.00.000
A36: 35 | B36: TT_S3_TM__02480 | C36: Phớt chắn bụi V-ring VA-25 | D36: Phớt chắn bụi VA-25 Loại phớt: V-ring | E36: Phớt chắn bụi V-ring VA-25 | F36: Cái | G36: Cái | H36: 5 | I36: 5 | J36: 470000 | K36: 0.08 | L36: =H36*J36 -> 2350000 | M36: =L36*(1+K36) -> 2538000 | N36: =K36*L36 -> 188000 | O36: Vật tư/Thiết bị cơ khí | P36: =M36/2 -> 1269000 | Q36: =1.5*(H36*30/365) -> 0.61643836 | R36: =1.5*H36 -> 7.5 | S36: =ROUND(Q36,2) -> 0.62 | T36: =ROUND(R36,2) -> 7.5 | U36: =S36&" sản phẩm/tháng hoặc " &T36& " sản phẩm/năm " -> 0,62 sản phẩm/tháng hoặc 7,5 sản phẩm/năm | W36: 150 ngày | X36: Đơn giá thấp nhất trong các báo giá | Y36: SKF/ Thụy Sĩ | Z36: 4.88.65.145.TPE.00.000 | AA36: 90000 | AB36: =VLOOKUP(Z36,'[1]Tra giá ERP'!$A$2:$C$25844,3,0) -> Nhập kho vật tư (HĐ:128/2022) theo hóa đơn số 938, 939 ngày 14.12.2022 | AC36: 0 | AD36: 0 | AE36: 5 | AG36: Điều chỉnh tên, TSKT theo ERP | AH36: 498000 | AI36: SKF/ Thái Lan | AJ36: 550000 | AK36: SKF/ Malaysia | AL36: 470000 | AM36: SKF/ Thụy Sĩ | AN36: Phớt chắn bụi VA-025 | AO36: Cái | AP36: 5 | AQ36: 4.88.65.145.TPE.00.000
A37: 36 | B37: TT_S3_TM__02514 | C37: Bạc đạn | D37: Bạc đạn 6204-2Z/C3 Đường kính trong (d): 20 mm Đường kính ngoài (D): 47 mm Độ dày (B): 14 mm | E37: Bạc đạn 6204-2Z/C3 | F37: Vòng | G37: Vòng | H37: 4 | I37: 4 | J37: 730000 | K37: 0.08 | L37: =H37*J37 -> 2920000 | M37: =L37*(1+K37) -> 3153600 | N37: =K37*L37 -> 233600 | O37: Vật tư/Thiết bị cơ khí | P37: =M37/2 -> 1576800 | Q37: =1.5*(H37*30/365) -> 0.49315068 | R37: =1.5*H37 -> 6 | S37: =ROUND(Q37,2) -> 0.49 | T37: =ROUND(R37,2) -> 6 | U37: =S37&" sản phẩm/tháng hoặc " &T37& " sản phẩm/năm " -> 0,49 sản phẩm/tháng hoặc 6 sản phẩm/năm | W37: 150 ngày | X37: Đơn giá thấp nhất trong các báo giá | Y37: SKF/ Trung Quốc | Z37: 5.01.34.241.FRA.00.000 | AA37: 111000 | AB37: =VLOOKUP(Z37,'[1]Tra giá ERP'!$A$2:$C$25844,3,0) -> Nhập kho Bạc đạn (HĐ:223) theo hóa đơn số 0000792 ngày 31.12.2020 ngày 23.12.2020 (phiếu sai) | AC37: 2 | AD37: 2 | AE37: 6 | AF37: 5.01.34.241.FRA.00.000 | AG37: Cách ly 03 vòng | AH37: 870000 | AI37: SKF/ Mỹ | AJ37: 983000 | AK37: SKF/ Malaysia | AL37: 730000 | AM37: SKF/ Trung Quốc | AN37: Vòng bi 6204 ZZ/C3 | AO37: Cái | AP37: 6 | AQ37: 5.01.34.241.FRA.00.000
A38: 37 | B38: TT_S3_TM__02515 | C38: Bạc đạn | D38: Bạc đạn 6203-2Z/C3 Đường kính trong (d): 17 mm Đường kính ngoài (D): 40 mm Độ dày (B): 12 mm | E38: Bạc đạn 6203-2Z/C3 | F38: Cái | G38: Cái | H38: 6 | I38: 6 | J38: 690000 | K38: 0.08 | L38: =H38*J38 -> 4140000 | M38: =L38*(1+K38) -> 4471200 | N38: =K38*L38 -> 331200 | O38: Vật tư/Thiết bị cơ khí | P38: =M38/2 -> 2235600 | Q38: =1.5*(H38*30/365) -> 0.73972603 | R38: =1.5*H38 -> 9 | S38: =ROUND(Q38,2) -> 0.74 | T38: =ROUND(R38,2) -> 9 | U38: =S38&" sản phẩm/tháng hoặc " &T38& " sản phẩm/năm " -> 0,74 sản phẩm/tháng hoặc 9 sản phẩm/năm | W38: 150 ngày | X38: Đơn giá thấp nhất trong các báo giá | Y38: SKF/ Trung Quốc | Z38: 5.01.34.203.ITA.00.000 | AA38: 92100 | AB38: =VLOOKUP(Z38,'[1]Tra giá ERP'!$A$2:$C$25844,3,0) -> Nhập kho Vật tư (QĐ:667) theo hóa đơn số 0000411 ngày 23.06.2020 | AC38: 0 | AD38: 0 | AE38: 6 | AG38: Điều chỉnh tên, TSKT theo ERP | AH38: 715000 | AI38: SKF/ Trung Quốc | AJ38: 890000 | AK38: SKF/ Malaysia | AL38: 690000 | AM38: SKF/ Trung Quốc | AN38: Vòng bi 6203 ZZ/C3 | AO38: Cái | AP38: 6 | AQ38: 5.01.34.203.ITA.00.000
A39: 38 | B39: TT_S3_TM__02516 | C39: Phớt chắn bụi V-20A | D39: Phớt chắn bụi V-20A Loại phớt: V-ring | E39: Phớt chắn bụi V-20A | F39: Cái | G39: Cái | H39: 6 | I39: 6 | J39: 155000 | K39: 0.08 | L39: =H39*J39 -> 930000 | M39: =L39*(1+K39) -> 1004400 | N39: =K39*L39 -> 74400 | O39: Vật tư/Thiết bị cơ khí | P39: =M39/2 -> 502200 | Q39: =1.5*(H39*30/365) -> 0.73972603 | R39: =1.5*H39 -> 9 | S39: =ROUND(Q39,2) -> 0.74 | T39: =ROUND(R39,2) -> 9 | U39: =S39&" sản phẩm/tháng hoặc " &T39& " sản phẩm/năm " -> 0,74 sản phẩm/tháng hoặc 9 sản phẩm/năm | W39: 150 ngày | X39: Đơn giá thấp nhất trong các báo giá | Y39: SKF/ Ý | Z39: 4.88.65.262.TPE.00.000 | AA39: 30000 | AB39: =VLOOKUP(Z39,'[1]Tra giá ERP'!$A$2:$C$25844,3,0) -> Nhập kho vật tư (HĐ:128/2022) theo hóa đơn số 938, 939 ngày 14.12.2022 | AC39: 0 | AD39: 0 | AE39: 6 | AG39: Điều chỉnh tên, TSKT theo ERP | AH39: 250000 | AI39: SKF/ Trung Quốc | AJ39: 220000 | AK39: SKF/ Ý | AL39: 155000 | AM39: SKF/ Ý | AN39: Phớt chắn bụi VA-020 | AO39: Cái | AP39: 6 | AQ39: 4.88.65.262.TPE.00.000
A40: 39 | B40: TT_S3_TM__02517 | C40: Phớt chắn bụi VA-015 | D40: Phớt chắn bụi VA-015 Loại phớt: V-ring | E40: #N/A | F40: #N/A | G40: Cái | H40: 6 | I40: 6 | J40: 750000 | K40: 0.08 | L40: =H40*J40 -> 4500000 | M40: =L40*(1+K40) -> 4860000 | N40: =K40*L40 -> 360000 | O40: Vật tư/Thiết bị cơ khí | P40: =M40/2 -> 2430000 | Q40: =1.5*(H40*30/365) -> 0.73972603 | R40: =1.5*H40 -> 9 | S40: =ROUND(Q40,2) -> 0.74 | T40: =ROUND(R40,2) -> 9 | U40: =S40&" sản phẩm/tháng hoặc " &T40& " sản phẩm/năm " -> 0,74 sản phẩm/tháng hoặc 9 sản phẩm/năm | W40: 150 ngày | X40: Đơn giá thấp nhất trong các báo giá | Y40: SKF/ Đức | Z40: Chưa có mã VT | AA40: #N/A | AB40: =VLOOKUP(Z40,'[1]Tra giá ERP'!$A$2:$C$25844,3,0) -> #N/A | AC40: 0 | AD40: 0 | AE40: 6 | AH40: 965000 | AI40: SKF/ Trung Quốc | AJ40: 1200000 | AK40: SKF/ Pháp | AL40: 750000 | AM40: SKF/ Đức | AN40: Phớt chắn bụi VA-015 | AO40: Cái | AP40: 6 | AQ40: Chưa có mã VT
...

Sheet TTD-Full-specs
A1: 2026-04-10 Ý kiến thẩm định về tính đầy đủ, rõ ràng của HSMT- phần chương V - bảng yêu cầu Kỹ thuật chi tiết
A2: STT | B2: ='hsmt v2'!C1 -> Tên vật tư mới | C2: ='hsmt v2'!D1 -> TSKT mới | D2: Đánh giá về tính đầy đủ
A3: 1 | B3: ='hsmt v2'!C2 -> Ổ cứng HDD | C3: ='hsmt v2'!D2 -> Ổ cứng HDD Hãng: WD Ổ cứng HDD 3.5 1TB Loại và tốc độ: SATA 6Gb/s Capacity: 1TB Thông số làm việc : 5V/0.68A; 12V/0.55A
A4: 2 | B4: ='hsmt v2'!C3 -> Mounting Base: HBS 01 - EPD | C4: ='hsmt v2'!D3 -> Đế Module IO Mác, mã: HBS01-EPD Hãng sản xuất: ABB PR (Product Revision): J hoặc mới hơn
A5: 3 | B5: ='hsmt v2'!C4 -> Đế gắn module IO SD I/O MOUNTING BASE Model: HBS01-FPH | C5: ='hsmt v2'!D4 -> Đế Module IO Mác, mã: HBS01-FPH Hãng sản xuất: ABB PR (Product Revision): J hoặc mới hơn
A6: 4 | B6: ='hsmt v2'!C5 -> Mouting base Model: HBS01-FPN | C6: ='hsmt v2'!D5 -> Đế Module IO Mác, mã: HBS01-FPN Hãng sản xuất: ABB PR (Product Revision): J hoặc mới hơn
A7: 5 | B7: ='hsmt v2'!C6 -> Túi chống ẩm Silicagel có dây treo 0,5kg/túi | C7: ='hsmt v2'!D6 -> Túi chống ẩm Silicagel có dây treo 0,5kg/túi
A8: 6 | B8: ='hsmt v2'!C7 -> Quạt hút tủ điện SNUON 300x300mm | C8: ='hsmt v2'!D7 -> Quạt hút tủ điện SNUON 300x300mm: Điện áp: 200V – 240V Hãng: SNUON Kích thước: 300x300x38mm Tốc độ: 2800-3250rpm Cánh quạt làm bằng nhựa Plastic cao cấp Khung quạt làm bằng kim loại: Chắc chắn
A9: 7 | B9: ='hsmt v2'!C8 -> Ổ cứng SSD Samsung 870 Evo 1TB | C9: ='hsmt v2'!D8 -> SSD Samsung 870 Evo 1TB Kích thước: 2.5-Inch SATA III MZ-77E1T0BW
A10: 8 | B10: ='hsmt v2'!C9 -> Công tắc (Switch) Model: DZ-10GW-1B | C10: ='hsmt v2'!D9 -> Công tắc (Switch) Model: DZ-10GW-1B Điện áp max: 250 VAC/VDC Dòng điện định mức: 10A Số công tắc: DPDT NSX: Omron
A11: 9 | B11: ='hsmt v2'!C10 -> Vòng đệm tròn cao su/O-ring, KT: ID456.06x5.33mm, vật liệu: Viton | C11: ='hsmt v2'!D10 -> Vòng đệm tròn cao su/O-ring - Kích thước: ID 456.06 x 5.33 mm - Vật liệu: Viton
A12: 10 | B12: ='hsmt v2'!C11 -> Vòng đệm tròn cao su/O-ring, Kích thước: ID 53.34 x 5.33 mm | C12: ='hsmt v2'!D11 -> Vòng đệm tròn cao su/O-ring - Kích thước: ID 53.34 x 5.33 mm - Vật liệu: Viton
A13: 11 | B13: ='hsmt v2'!C12 -> Vòng đệm tròn cao su/O-ring, KT: ID46.99x5.33mm, vật liệu: Viton | C13: ='hsmt v2'!D12 -> Vòng đệm tròn cao su/O-ring - Kích thước: ID 46.99 x 5.33 mm - Vật liệu: Viton
A14: 12 | B14: ='hsmt v2'!C13 -> Vòng đệm tròn cao su/O-ring, KT: ID 69.44x3.53mm, vật liệu: Viton | C14: ='hsmt v2'!D13 -> Vòng đệm tròn cao su/O-ring - Kích thước: ID 69.44 x 3.53 mm - Vật liệu: Viton
... A308: 306 | B308: ='hsmt v2'!C307 -> Gói dịch vụ | C308: ='hsmt v2'!D307 -> Gói dịch vụ đính kèm trong Tờ trình 849/KTAT ngày 01/03/2026 v/v phương án tái lập hệ thống nhận, truyền và quản lý dữ liệu quan trắc cho hệ thống quan trắc tự động, liên tục Nhà máy Nhiệt điện Vĩnh Tân 4

Sheet TTD-CO_CQ
B1: 2026-04-10-Ý kiến thẩm định HSMT gói thầu 39
E2: =SUM(D:D) -> 2.2083336e+09 | F2: =E2/'hsmt v2'!M316 -> 0.029736639
A3: STT | B3: ='hsmt v2'!$C$1 -> Tên vật tư mới | C3: TSKT | D3: ='hsmt v2'!$M$1 -> Thành tiền sau thuế | E3: Hãng báo giá | F3: Nhập khẩu | G3: Tình Trạng yêu cầu CO CQ HSMT | H3: Nhận xét
A4: 179 | B4: ='hsmt v2'!C307 -> Gói dịch vụ | C4: ='hsmt v2'!$D$307 -> Gói dịch vụ đính kèm trong Tờ trình 849/KTAT ngày 01/03/2026 v/v phương án tái lập hệ thống nhận, truyền và quản lý dữ liệu quan trắc cho hệ thống quan trắc tự động, liên tục Nhà máy Nhiệt điện Vĩnh Tân 4 | D4: ='hsmt v2'!$M$307 -> 167400000 | E4: ='hsmt v2'!Y307 -> 0 | F4: sai | G4: Không yêu cầu CO, CQ | H4: Là dịch vụ
A5: 22 | B5: ='hsmt v2'!C31 -> Bộ điều chỉnh khí nén, Mã: LFR-3/4-D-MAXI-A | C5: ='hsmt v2'!D31 -> Bộ điều áp (Regulator) Model: LFR-3/4-D-MAXI-A Order code: 159636; Type: Filter regulator with pressure gauge; Operating pressure: 2 ~ 12 bar; Grade of filtration: 40 µm; Connection: G ¾ inch NSX : Festo | D5: ='hsmt v2'!M31 -> 139320000 | E5: ='hsmt v2'!Y31 -> Rotork YTC/ Hàn Quốc | F5: OK | G5: Không yêu cầu CO, CQ | H5: Bổ sung lý do vì sao là hàng nhập khẩu nhưng ko yêu cầu CO, CQ
A6: 10 | B6: ='hsmt v2'!C15 -> Van điện từ/Solenoid valve, Model: 8316P064, 10-250 psi, 110-240 VAC | C6: ='hsmt v2'!D15 -> Van điện từ/Solenoid valve: - Model: 8316P064 - Voltage: 110-240VAC 50Hz, 2W - Inert gas: 10-250 psi Manufacturer: ASCO | D6: ='hsmt v2'!M15 -> 79920000 | E6: ='hsmt v2'!Y15 -> ASCO/ Singapore | F6: OK | G6: Không yêu cầu CO, CQ | H6: Bổ sung lý do vì sao là hàng nhập khẩu nhưng ko yêu cầu CO, CQ
A7: 90 | B7: ='hsmt v2'!C134 -> Bộ chỉnh áp điều chỉnh khí nén, Model: YT-200BN210 | C7: ='hsmt v2'!D134 -> Bộ chỉnh áp điều chỉnh khí nén (Air regulator) Model: YT-200BN210 Air Connection: NPT 1/4 Adjust Range: 0 - 8.4 bar Gauges: one Max. Supply: 1.7 Mpa Bao gồm đồng hồ NSX : Rotork YTC | D7: ='hsmt v2'!M134 -> 60264000 | E7: ='hsmt v2'!Y134 -> Rotork YTC/ Hàn Quốc | F7: OK | G7: Không yêu cầu CO, CQ | H7: Bổ sung lý do vì sao là hàng nhập khẩu nhưng ko yêu cầu CO, CQ
A8: 77 | B8: ='hsmt v2'!C106 -> Gasket Chesterton SWG size 12"x300#, 316L/316L/FG | C8: ='hsmt v2'!D106 -> Gasket Chesterton SWG size 12"x300#, 316L/316L/FG | D8: ='hsmt v2'!M106 -> 49372200 | E8: ='hsmt v2'!Y106 -> HTC/ Trung Quốc | F8: OK | G8: Không yêu cầu CO, CQ | H8: Bổ sung lý do vì sao là hàng nhập khẩu nhưng ko yêu cầu CO, CQ
A9: 60 | B9: ='hsmt v2'!C77 -> Vòng đệm tròn làm kín (O-ring) pos 37, sử dụng cho bơm EH có Model: MKV-23ME-RFA | C9: ='hsmt v2'!D77 -> Vòng đệm tròn làm kín (O-ring) pos 37, part no: 363-204-043-6, sử dụng cho bơm EH, tiêu chuẩn AS568 256 Hs70 (Bơm EH có Model: MKV-23ME-RFA, Dw no: DA2301-179-0, NSX bơm: Mitsubishi) | D9: ='hsmt v2'!M77 -> 42552000 | E9: ='hsmt v2'!Y77 -> Mitsubishi/ Trung Quốc | F9: OK | G9: Không yêu cầu CO, CQ | H9: Bổ sung lý do vì sao là hàng nhập khẩu nhưng ko yêu cầu CO, CQ
A10: 82 | B10: ='hsmt v2'!C119 -> Co 90 độ, KT: DN80, LR, BW, S-10S, Vật liệu: A815 CL WPS31803 | C10: ='hsmt v2'!D119 -> Co ống 90D: DN80, LR, BW, S-10S. Vật liệu: A815 CL WPS31803 | D10: ='hsmt v2'!M119 -> 42120000 | E10: ='hsmt v2'!Y119 -> Baosteel/ Trung Quốc | F10: OK | G10: Không yêu cầu CO, CQ | H10: Bổ sung lý do vì sao là hàng nhập khẩu nhưng ko yêu cầu CO, CQ
A11: 97 | B11: ='hsmt v2'!C145 -> Relay khuếch đại/ booster relay, Model: YT-320N1, Air connection: 1/2 NPT; Pressure: max 1 MPA | C11: ='hsmt v2'!D145 -> Relay khuếch đại/ booster relay: - Model : YT-320N1 - Air connection: 1/2 NPT - Max.Sup press: 1Mpa - Max.Sig/Out: 0.7 Mpa - Maker: Rotork YTC | D11: ='hsmt v2'!M145 -> 39730999 | E11: ='hsmt v2'!Y145 -> Rotork YTC/ Hàn Quốc | F11: OK | G11: Không yêu cầu CO, CQ | H11: Bổ sung lý do vì sao là hàng nhập khẩu nhưng ko yêu cầu CO, CQ
A12: 13 | B12: ='hsmt v2'!C22 -> Nhựa tấm teflon (PTFE tấm), KT: 1000mmx1000mmx04mm | C12: ='hsmt v2'!D22 -> Nhựa tấm teflon (PTFE tấm), KT: 1000mmx1000mmx04mm | D12: ='hsmt v2'!M22 -> 39683520 | E12: ='hsmt v2'!Y22 -> YUANYU/ Trung Quốc | F12: OK | G12: Không yêu cầu CO, CQ | H12: Bổ sung lý do vì sao là hàng nhập khẩu nhưng ko yêu cầu CO, CQ
A13: 78 | B13: ='hsmt v2'!C110 -> Vòng đệm làm kín/ bonnet gasket, pos 13, sử dụng cho van van xả dồn BGN 3 về 2, serial no: 24644 | C13: ='hsmt v2'!D110 -> Vòng đệm tròn làm kín/bonnet gasket pos 13; vật liệu:GTP & SS304; (sử dụng cho van xả dồn BGN 3 về 2 có model BV 500 ; class 150# body size: 8'' ;serial No: 24664; NSX:WEIR) | D13: ='hsmt v2'!M110 -> 34020000 | E13: ='hsmt v2'!Y110 -> WEIR/ Hàn Quốc | F13: OK | G13: Không yêu cầu CO, CQ | H13: Bổ sung lý do vì sao là hàng nhập khẩu nhưng ko yêu cầu CO, CQ
A14: 79 | B14: ='hsmt v2'!C111 -> Vòng đệm tròn làm kín/ cage gaket pos 14, sử dụng cho van xả dồn BGN 3 về 2, serial no: 24644 | C14: ='hsmt v2'!D111 -> Vòng đệm tròn làm kín/cage gasket pos14; vật liệu:GTP & SS304; (sử dụng cho van xả dồn BGN 3 về 2 có model BV 500 ; class 150# body size: 8'' ;serial No: 24664; NSX:WEIR) | D14: ='hsmt v2'!M111 -> 34020000 | E14: ='hsmt v2'!Y111 -> WEIR/ Hàn Quốc | F14: OK | G14: Không yêu cầu CO, CQ | H14: Bổ sung lý do vì sao là hàng nhập khẩu nhưng ko yêu cầu CO, CQ
A15: 80 | B15: ='hsmt v2'!C112 -> Vòng đệm tròn làm kín/ seat gasket pos 15, sử dụng cho van xả dồn BGN 3 về 2, serial no: 24644 | C15: ='hsmt v2'!D112 -> Vòng đệm tròn làm kín/seat gasket pos15; vật liệu:GTP & SS304; (sử dụng cho van xả dồn BGN 3 về 2 có model BV 500 ; class 150# body size: 8'' ;serial No: 24664; NSX:WEIR) | D15: ='hsmt v2'!M112 -> 34020000 | E15: ='hsmt v2'!Y112 -> WEIR/ Hàn Quốc | F15: OK | G15: Không yêu cầu CO, CQ | H15: Bổ sung lý do vì sao là hàng nhập khẩu nhưng ko yêu cầu CO, CQ
A16: 2 | B16: ='hsmt v2'!C7 -> Quạt hút tủ điện SNUON 300x300mm | C16: ='hsmt v2'!D7 -> Quạt hút tủ điện SNUON 300x300mm: Điện áp: 200V – 240V Hãng: SNUON Kích thước: 300x300x38mm Tốc độ: 2800-3250rpm Cánh quạt làm bằng nhựa Plastic cao cấp Khung quạt làm bằng kim loại: Chắc chắn | D16: ='hsmt v2'!M7 -> 33102000 | E16: ='hsmt v2'!Y7 -> SNUON/ Thái Lan | F16: OK | G16: Không yêu cầu CO, CQ | H16: Bổ sung lý do vì sao là hàng nhập khẩu nhưng ko yêu cầu CO, CQ
A17: 139 | B17: ='hsmt v2'!C212 -> Vòng phớt làm kín/ U seal pos 09 sử dụng cho van serial no: 24648 | C17: ='hsmt v2'!D212 -> Vòng phớt làm kín (U seal carbon) pos 09 (sử dụng cho van BV990 class 1500, body size 6'' NSX : WEIR; van có serial NO: 24648) | D17: ='hsmt v2'!M212 -> 31339872 | E17: ='hsmt v2'!Y212 -> WEIR/ Hàn Quốc | F17: OK | G17: Không yêu cầu CO, CQ | H17: Bổ sung lý do vì sao là hàng nhập khẩu nhưng ko yêu cầu CO, CQ
A18: 11 | B18: ='hsmt v2'!C16 -> Van điện từ/ Solenoid valve | C18: ='hsmt v2'!D16 -> Van điện từ/ Solenoid valve: - Model: 8316P066 - Voltage: 110-240VAC 50Hz, 2W - Inert gas: 10-250 psi Manufacturer: ASCO | D18: ='hsmt v2'!M16 -> 30996000 | E18: ='hsmt v2'!Y16 -> ASCO/ Singapore | F18: OK | G18: Không yêu cầu CO, CQ | H18: Bổ sung lý do vì sao là hàng nhập khẩu nhưng ko yêu cầu CO, CQ
A19: 156 | B19: ='hsmt v2'!C255 -> Lõi lọc trước (Pre filter element) FR12-010P-F | C19: ='hsmt v2'!$D$255 -> Lõi lọc trước/ Pre filter element FR12-010P-F Maker: SANMI | D19: ='hsmt v2'!$M$255 -> 30758400 | E19: ='hsmt v2'!Y255 -> SANMI/ Đức | F19: OK | G19: Không yêu cầu CO, CQ | H19: Bổ sung lý do vì sao là hàng nhập khẩu nhưng ko yêu cầu CO, CQ
